  NAMES
11c4b73e84f4   matrixdotorg/synapse:latest   "/start.py"   15 minutes ago   Restarting (1) 54 seconds ago             matrix-synapse
2f941eed4a98   hello-world                   "/hello"      49 minutes ago   Exited (0) 49 minutes ago                 infallible_spence
ubuntu@vps-2b9a3549:/srv/matrix-synapse$ sudo docker logs matrix-synapse
Starting synapse with args -m synapse.app.homeserver --config-path /data/homeserver.yaml
Traceback (most recent call last):
  File "<frozen runpy>", line 198, in _run_module_as_main
  File "<frozen runpy>", line 88, in _run_code
  File "/usr/local/lib/python3.12/site-packages/synapse/app/homeserver.py", line 421, in <module>
    main()
  File "/usr/local/lib/python3.12/site-packages/synapse/app/homeserver.py", line 411, in main
    hs = setup(sys.argv[1:])
         ^^^^^^^^^^^^^^^^^^^
  File "/usr/local/lib/python3.12/site-packages/synapse/app/homeserver.py", line 320, in setup
    config = HomeServerConfig.load_or_generate_config(
             ^^^^^^^^^^^^^^^^^^^^^^^^^^^^^^^^^^^^^^^^^
  File "/usr/local/lib/python3.12/site-packages/synapse/config/_base.py", line 833, in load_or_generate_config
    obj.generate_missing_files(config_dict, config_dir_path)
  File "/usr/local/lib/python3.12/site-packages/synapse/config/_base.py", line 880, in generate_missing_files
    self.invoke_all("generate_files", config_dict, config_dir_path)
  File "/usr/local/lib/python3.12/site-packages/synapse/config/_base.py", line 443, in invoke_all
    res[config_class.section] = getattr(config, func_name)(*args, **kwargs)
                                ^^^^^^^^^^^^^^^^^^^^^^^^^^^^^^^^^^^^^^^^^^^
  File "/usr/local/lib/python3.12/site-packages/synapse/config/logger.py", line 198, in generate_files
    with open(log_config, "w") as log_config_file:
         ^^^^^^^^^^^^^^^^^^^^^
PermissionError: [Errno 13] Permission denied: '/data/rubberroomwithrats.com.log.config'
Generating log config file /data/rubberroomwithrats.com.log.config which will log to /homeserver.log
Starting synapse with args -m synapse.app.homeserver --config-path /data/homeserver.yaml
Traceback (most recent call last):
  File "<frozen runpy>", line 198, in _run_module_as_main
  File "<frozen runpy>", line 88, in _run_code
  File "/usr/local/lib/python3.12/site-packages/synapse/app/homeserver.py", line 421, in <module>
    main()
  File "/usr/local/lib/python3.12/site-packages/synapse/app/homeserver.py", line 411, in main
    hs = setup(sys.argv[1:])
         ^^^^^^^^^^^^^^^^^^^
  File "/usr/local/lib/python3.12/site-packages/synapse/app/homeserver.py", line 320, in setup
    config = HomeServerConfig.load_or_generate_config(
             ^^^^^^^^^^^^^^^^^^^^^^^^^^^^^^^^^^^^^^^^^
  File "/usr/local/lib/python3.12/site-packages/synapse/config/_base.py", line 833, in load_or_generate_config
    obj.generate_missing_files(config_dict, config_dir_path)
  File "/usr/local/lib/python3.12/site-packages/synapse/config/_base.py", line 880, in generate_missing_files
    self.invoke_all("generate_files", config_dict, config_dir_path)
  File "/usr/local/lib/python3.12/site-packages/synapse/config/_base.py", line 443, in invoke_all
    res[config_class.section] = getattr(config, func_name)(*args, **kwargs)
                                ^^^^^^^^^^^^^^^^^^^^^^^^^^^^^^^^^^^^^^^^^^^
  File "/usr/local/lib/python3.12/site-packages/synapse/config/logger.py", line 198, in generate_files
    with open(log_config, "w") as log_config_file:
         ^^^^^^^^^^^^^^^^^^^^^
PermissionError: [Errno 13] Permission denied: '/data/rubberroomwithrats.com.log.config'
Generating log config file /data/rubberroomwithrats.com.log.config which will log to /homeserver.log
Starting synapse with args -m synapse.app.homeserver --config-path /data/homeserver.yaml
Traceback (most recent call last):
  File "<frozen runpy>", line 198, in _run_module_as_main
  File "<frozen runpy>", line 88, in _run_code
  File "/usr/local/lib/python3.12/site-packages/synapse/app/homeserver.py", line 421, in <module>
    main()
  File "/usr/local/lib/python3.12/site-packages/synapse/app/homeserver.py", line 411, in main
    hs = setup(sys.argv[1:])
         ^^^^^^^^^^^^^^^^^^^
  File "/usr/local/lib/python3.12/site-packages/synapse/app/homeserver.py", line 320, in setup
    config = HomeServerConfig.load_or_generate_config(
             ^^^^^^^^^^^^^^^^^^^^^^^^^^^^^^^^^^^^^^^^^
  File "/usr/local/lib/python3.12/site-packages/synapse/config/_base.py", line 833, in load_or_generate_config
    obj.generate_missing_files(config_dict, config_dir_path)
  File "/usr/local/lib/python3.12/site-packages/synapse/config/_base.py", line 880, in generate_missing_files
    self.invoke_all("generate_files", config_dict, config_dir_path)
  File "/usr/local/lib/python3.12/site-packages/synapse/config/_base.py", line 443, in invoke_all
    res[config_class.section] = getattr(config, func_name)(*args, **kwargs)
                                ^^^^^^^^^^^^^^^^^^^^^^^^^^^^^^^^^^^^^^^^^^^
  File "/usr/local/lib/python3.12/site-packages/synapse/config/logger.py", line 198, in generate_files
    with open(log_config, "w") as log_config_file:
         ^^^^^^^^^^^^^^^^^^^^^
PermissionError: [Errno 13] Permission denied: '/data/rubberroomwithrats.com.log.config'
Generating log config file /data/rubberroomwithrats.com.log.config which will log to /homeserver.log
Starting synapse with args -m synapse.app.homeserver --config-path /data/homeserver.yaml
Traceback (most recent call last):
  File "<frozen runpy>", line 198, in _run_module_as_main
  File "<frozen runpy>", line 88, in _run_code
  File "/usr/local/lib/python3.12/site-packages/synapse/app/homeserver.py", line 421, in <module>
    main()
  File "/usr/local/lib/python3.12/site-packages/synapse/app/homeserver.py", line 411, in main
    hs = setup(sys.argv[1:])
         ^^^^^^^^^^^^^^^^^^^
  File "/usr/local/lib/python3.12/site-packages/synapse/app/homeserver.py", line 320, in setup
    config = HomeServerConfig.load_or_generate_config(
             ^^^^^^^^^^^^^^^^^^^^^^^^^^^^^^^^^^^^^^^^^
  File "/usr/local/lib/python3.12/site-packages/synapse/config/_base.py", line 833, in load_or_generate_config
    obj.generate_missing_files(config_dict, config_dir_path)
  File "/usr/local/lib/python3.12/site-packages/synapse/config/_base.py", line 880, in generate_missing_files
    self.invoke_all("generate_files", config_dict, config_dir_path)
  File "/usr/local/lib/python3.12/site-packages/synapse/config/_base.py", line 443, in invoke_all
    res[config_class.section] = getattr(config, func_name)(*args, **kwargs)
                                ^^^^^^^^^^^^^^^^^^^^^^^^^^^^^^^^^^^^^^^^^^^
  File "/usr/local/lib/python3.12/site-packages/synapse/config/logger.py", line 198, in generate_files
    with open(log_config, "w") as log_config_file:
         ^^^^^^^^^^^^^^^^^^^^^
PermissionError: [Errno 13] Permission denied: '/data/rubberroomwithrats.com.log.config'
Generating log config file /data/rubberroomwithrats.com.log.config which will log to /homeserver.log
Starting synapse with args -m synapse.app.homeserver --config-path /data/homeserver.yaml
Traceback (most recent call last):
  File "<frozen runpy>", line 198, in _run_module_as_main
  File "<frozen runpy>", line 88, in _run_code
  File "/usr/local/lib/python3.12/site-packages/synapse/app/homeserver.py", line 421, in <module>
    main()
  File "/usr/local/lib/python3.12/site-packages/synapse/app/homeserver.py", line 411, in main
    hs = setup(sys.argv[1:])
         ^^^^^^^^^^^^^^^^^^^
  File "/usr/local/lib/python3.12/site-packages/synapse/app/homeserver.py", line 320, in setup
    config = HomeServerConfig.load_or_generate_config(
             ^^^^^^^^^^^^^^^^^^^^^^^^^^^^^^^^^^^^^^^^^
  File "/usr/local/lib/python3.12/site-packages/synapse/config/_base.py", line 833, in load_or_generate_config
    obj.generate_missing_files(config_dict, config_dir_path)
  File "/usr/local/lib/python3.12/site-packages/synapse/config/_base.py", line 880, in generate_missing_files
    self.invoke_all("generate_files", config_dict, config_dir_path)
  File "/usr/local/lib/python3.12/site-packages/synapse/config/_base.py", line 443, in invoke_all
    res[config_class.section] = getattr(config, func_name)(*args, **kwargs)
                                ^^^^^^^^^^^^^^^^^^^^^^^^^^^^^^^^^^^^^^^^^^^
  File "/usr/local/lib/python3.12/site-packages/synapse/config/logger.py", line 198, in generate_files
    with open(log_config, "w") as log_config_file:
         ^^^^^^^^^^^^^^^^^^^^^
PermissionError: [Errno 13] Permission denied: '/data/rubberroomwithrats.com.log.config'
Generating log config file /data/rubberroomwithrats.com.log.config which will log to /homeserver.log
Starting synapse with args -m synapse.app.homeserver --config-path /data/homeserver.yaml
Traceback (most recent call last):
  File "<frozen runpy>", line 198, in _run_module_as_main
  File "<frozen runpy>", line 88, in _run_code
  File "/usr/local/lib/python3.12/site-packages/synapse/app/homeserver.py", line 421, in <module>
    main()
  File "/usr/local/lib/python3.12/site-packages/synapse/app/homeserver.py", line 411, in main
    hs = setup(sys.argv[1:])
         ^^^^^^^^^^^^^^^^^^^
  File "/usr/local/lib/python3.12/site-packages/synapse/app/homeserver.py", line 320, in setup
    config = HomeServerConfig.load_or_generate_config(
             ^^^^^^^^^^^^^^^^^^^^^^^^^^^^^^^^^^^^^^^^^
  File "/usr/local/lib/python3.12/site-packages/synapse/config/_base.py", line 833, in load_or_generate_config
    obj.generate_missing_files(config_dict, config_dir_path)
  File "/usr/local/lib/python3.12/site-packages/synapse/config/_base.py", line 880, in generate_missing_files
    self.invoke_all("generate_files", config_dict, config_dir_path)
  File "/usr/local/lib/python3.12/site-packages/synapse/config/_base.py", line 443, in invoke_all
    res[config_class.section] = getattr(config, func_name)(*args, **kwargs)
                                ^^^^^^^^^^^^^^^^^^^^^^^^^^^^^^^^^^^^^^^^^^^
  File "/usr/local/lib/python3.12/site-packages/synapse/config/logger.py", line 198, in generate_files
    with open(log_config, "w") as log_config_file:
         ^^^^^^^^^^^^^^^^^^^^^
PermissionError: [Errno 13] Permission denied: '/data/rubberroomwithrats.com.log.config'
Generating log config file /data/rubberroomwithrats.com.log.config which will log to /homeserver.log
Starting synapse with args -m synapse.app.homeserver --config-path /data/homeserver.yaml
Traceback (most recent call last):
  File "<frozen runpy>", line 198, in _run_module_as_main
  File "<frozen runpy>", line 88, in _run_code
  File "/usr/local/lib/python3.12/site-packages/synapse/app/homeserver.py", line 421, in <module>
    main()
  File "/usr/local/lib/python3.12/site-packages/synapse/app/homeserver.py", line 411, in main
    hs = setup(sys.argv[1:])
         ^^^^^^^^^^^^^^^^^^^
  File "/usr/local/lib/python3.12/site-packages/synapse/app/homeserver.py", line 320, in setup
    config = HomeServerConfig.load_or_generate_config(
             ^^^^^^^^^^^^^^^^^^^^^^^^^^^^^^^^^^^^^^^^^
  File "/usr/local/lib/python3.12/site-packages/synapse/config/_base.py", line 833, in load_or_generate_config
    obj.generate_missing_files(config_dict, config_dir_path)
  File "/usr/local/lib/python3.12/site-packages/synapse/config/_base.py", line 880, in generate_missing_files
    self.invoke_all("generate_files", config_dict, config_dir_path)
  File "/usr/local/lib/python3.12/site-packages/synapse/config/_base.py", line 443, in invoke_all
    res[config_class.section] = getattr(config, func_name)(*args, **kwargs)
                                ^^^^^^^^^^^^^^^^^^^^^^^^^^^^^^^^^^^^^^^^^^^
  File "/usr/local/lib/python3.12/site-packages/synapse/config/logger.py", line 198, in generate_files
    with open(log_config, "w") as log_config_file:
         ^^^^^^^^^^^^^^^^^^^^^
PermissionError: [Errno 13] Permission denied: '/data/rubberroomwithrats.com.log.config'
Generating log config file /data/rubberroomwithrats.com.log.config which will log to /homeserver.log
Starting synapse with args -m synapse.app.homeserver --config-path /data/homeserver.yaml
Traceback (most recent call last):
  File "<frozen runpy>", line 198, in _run_module_as_main
  File "<frozen runpy>", line 88, in _run_code
  File "/usr/local/lib/python3.12/site-packages/synapse/app/homeserver.py", line 421, in <module>
    main()
  File "/usr/local/lib/python3.12/site-packages/synapse/app/homeserver.py", line 411, in main
    hs = setup(sys.argv[1:])
         ^^^^^^^^^^^^^^^^^^^
  File "/usr/local/lib/python3.12/site-packages/synapse/app/homeserver.py", line 320, in setup
    config = HomeServerConfig.load_or_generate_config(
             ^^^^^^^^^^^^^^^^^^^^^^^^^^^^^^^^^^^^^^^^^
  File "/usr/local/lib/python3.12/site-packages/synapse/config/_base.py", line 833, in load_or_generate_config
    obj.generate_missing_files(config_dict, config_dir_path)
  File "/usr/local/lib/python3.12/site-packages/synapse/config/_base.py", line 880, in generate_missing_files
    self.invoke_all("generate_files", config_dict, config_dir_path)
  File "/usr/local/lib/python3.12/site-packages/synapse/config/_base.py", line 443, in invoke_all
    res[config_class.section] = getattr(config, func_name)(*args, **kwargs)
                                ^^^^^^^^^^^^^^^^^^^^^^^^^^^^^^^^^^^^^^^^^^^
  File "/usr/local/lib/python3.12/site-packages/synapse/config/logger.py", line 198, in generate_files
    with open(log_config, "w") as log_config_file:
         ^^^^^^^^^^^^^^^^^^^^^
PermissionError: [Errno 13] Permission denied: '/data/rubberroomwithrats.com.log.config'
Generating log config file /data/rubberroomwithrats.com.log.config which will log to /homeserver.log
Starting synapse with args -m synapse.app.homeserver --config-path /data/homeserver.yaml
Traceback (most recent call last):
  File "<frozen runpy>", line 198, in _run_module_as_main
  File "<frozen runpy>", line 88, in _run_code
  File "/usr/local/lib/python3.12/site-packages/synapse/app/homeserver.py", line 421, in <module>
    main()
  File "/usr/local/lib/python3.12/site-packages/synapse/app/homeserver.py", line 411, in main
    hs = setup(sys.argv[1:])
         ^^^^^^^^^^^^^^^^^^^
  File "/usr/local/lib/python3.12/site-packages/synapse/app/homeserver.py", line 320, in setup
    config = HomeServerConfig.load_or_generate_config(
             ^^^^^^^^^^^^^^^^^^^^^^^^^^^^^^^^^^^^^^^^^
  File "/usr/local/lib/python3.12/site-packages/synapse/config/_base.py", line 833, in load_or_generate_config
    obj.generate_missing_files(config_dict, config_dir_path)
  File "/usr/local/lib/python3.12/site-packages/synapse/config/_base.py", line 880, in generate_missing_files
    self.invoke_all("generate_files", config_dict, config_dir_path)
  File "/usr/local/lib/python3.12/site-packages/synapse/config/_base.py", line 443, in invoke_all
    res[config_class.section] = getattr(config, func_name)(*args, **kwargs)
                                ^^^^^^^^^^^^^^^^^^^^^^^^^^^^^^^^^^^^^^^^^^^
  File "/usr/local/lib/python3.12/site-packages/synapse/config/logger.py", line 198, in generate_files
    with open(log_config, "w") as log_config_file:
         ^^^^^^^^^^^^^^^^^^^^^
PermissionError: [Errno 13] Permission denied: '/data/rubberroomwithrats.com.log.config'
Generating log config file /data/rubberroomwithrats.com.log.config which will log to /homeserver.log
Starting synapse with args -m synapse.app.homeserver --config-path /data/homeserver.yaml
Traceback (most recent call last):
  File "<frozen runpy>", line 198, in _run_module_as_main
  File "<frozen runpy>", line 88, in _run_code
  File "/usr/local/lib/python3.12/site-packages/synapse/app/homeserver.py", line 421, in <module>
    main()
  File "/usr/local/lib/python3.12/site-packages/synapse/app/homeserver.py", line 411, in main
    hs = setup(sys.argv[1:])
         ^^^^^^^^^^^^^^^^^^^
  File "/usr/local/lib/python3.12/site-packages/synapse/app/homeserver.py", line 320, in setup
    config = HomeServerConfig.load_or_generate_config(
             ^^^^^^^^^^^^^^^^^^^^^^^^^^^^^^^^^^^^^^^^^
  File "/usr/local/lib/python3.12/site-packages/synapse/config/_base.py", line 833, in load_or_generate_config
    obj.generate_missing_files(config_dict, config_dir_path)
  File "/usr/local/lib/python3.12/site-packages/synapse/config/_base.py", line 880, in generate_missing_files
    self.invoke_all("generate_files", config_dict, config_dir_path)
  File "/usr/local/lib/python3.12/site-packages/synapse/config/_base.py", line 443, in invoke_all
    res[config_class.section] = getattr(config, func_name)(*args, **kwargs)
                                ^^^^^^^^^^^^^^^^^^^^^^^^^^^^^^^^^^^^^^^^^^^
  File "/usr/local/lib/python3.12/site-packages/synapse/config/logger.py", line 198, in generate_files
    with open(log_config, "w") as log_config_file:
         ^^^^^^^^^^^^^^^^^^^^^
PermissionError: [Errno 13] Permission denied: '/data/rubberroomwithrats.com.log.config'
Generating log config file /data/rubberroomwithrats.com.log.config which will log to /homeserver.log
Starting synapse with args -m synapse.app.homeserver --config-path /data/homeserver.yaml
Traceback (most recent call last):
  File "<frozen runpy>", line 198, in _run_module_as_main
  File "<frozen runpy>", line 88, in _run_code
  File "/usr/local/lib/python3.12/site-packages/synapse/app/homeserver.py", line 421, in <module>
    main()
  File "/usr/local/lib/python3.12/site-packages/synapse/app/homeserver.py", line 411, in main
    hs = setup(sys.argv[1:])
         ^^^^^^^^^^^^^^^^^^^
  File "/usr/local/lib/python3.12/site-packages/synapse/app/homeserver.py", line 320, in setup
    config = HomeServerConfig.load_or_generate_config(
             ^^^^^^^^^^^^^^^^^^^^^^^^^^^^^^^^^^^^^^^^^
  File "/usr/local/lib/python3.12/site-packages/synapse/config/_base.py", line 833, in load_or_generate_config
    obj.generate_missing_files(config_dict, config_dir_path)
  File "/usr/local/lib/python3.12/site-packages/synapse/config/_base.py", line 880, in generate_missing_files
    self.invoke_all("generate_files", config_dict, config_dir_path)
  File "/usr/local/lib/python3.12/site-packages/synapse/config/_base.py", line 443, in invoke_all
    res[config_class.section] = getattr(config, func_name)(*args, **kwargs)
                                ^^^^^^^^^^^^^^^^^^^^^^^^^^^^^^^^^^^^^^^^^^^
  File "/usr/local/lib/python3.12/site-packages/synapse/config/logger.py", line 198, in generate_files
    with open(log_config, "w") as log_config_file:
         ^^^^^^^^^^^^^^^^^^^^^
PermissionError: [Errno 13] Permission denied: '/data/rubberroomwithrats.com.log.config'
Generating log config file /data/rubberroomwithrats.com.log.config which will log to /homeserver.log
Starting synapse with args -m synapse.app.homeserver --config-path /data/homeserver.yaml
Traceback (most recent call last):
  File "<frozen runpy>", line 198, in _run_module_as_main
  File "<frozen runpy>", line 88, in _run_code
  File "/usr/local/lib/python3.12/site-packages/synapse/app/homeserver.py", line 421, in <module>
    main()
  File "/usr/local/lib/python3.12/site-packages/synapse/app/homeserver.py", line 411, in main
    hs = setup(sys.argv[1:])
         ^^^^^^^^^^^^^^^^^^^
  File "/usr/local/lib/python3.12/site-packages/synapse/app/homeserver.py", line 320, in setup
    config = HomeServerConfig.load_or_generate_config(
             ^^^^^^^^^^^^^^^^^^^^^^^^^^^^^^^^^^^^^^^^^
  File "/usr/local/lib/python3.12/site-packages/synapse/config/_base.py", line 833, in load_or_generate_config
    obj.generate_missing_files(config_dict, config_dir_path)
  File "/usr/local/lib/python3.12/site-packages/synapse/config/_base.py", line 880, in generate_missing_files
    self.invoke_all("generate_files", config_dict, config_dir_path)
  File "/usr/local/lib/python3.12/site-packages/synapse/config/_base.py", line 443, in invoke_all
    res[config_class.section] = getattr(config, func_name)(*args, **kwargs)
                                ^^^^^^^^^^^^^^^^^^^^^^^^^^^^^^^^^^^^^^^^^^^
  File "/usr/local/lib/python3.12/site-packages/synapse/config/logger.py", line 198, in generate_files
    with open(log_config, "w") as log_config_file:
         ^^^^^^^^^^^^^^^^^^^^^
PermissionError: [Errno 13] Permission denied: '/data/rubberroomwithrats.com.log.config'
Generating log config file /data/rubberroomwithrats.com.log.config which will log to /homeserver.log
Starting synapse with args -m synapse.app.homeserver --config-path /data/homeserver.yaml
Traceback (most recent call last):
  File "<frozen runpy>", line 198, in _run_module_as_main
  File "<frozen runpy>", line 88, in _run_code
  File "/usr/local/lib/python3.12/site-packages/synapse/app/homeserver.py", line 421, in <module>
    main()
  File "/usr/local/lib/python3.12/site-packages/synapse/app/homeserver.py", line 411, in main
    hs = setup(sys.argv[1:])
         ^^^^^^^^^^^^^^^^^^^
  File "/usr/local/lib/python3.12/site-packages/synapse/app/homeserver.py", line 320, in setup
    config = HomeServerConfig.load_or_generate_config(
             ^^^^^^^^^^^^^^^^^^^^^^^^^^^^^^^^^^^^^^^^^
  File "/usr/local/lib/python3.12/site-packages/synapse/config/_base.py", line 833, in load_or_generate_config
    obj.generate_missing_files(config_dict, config_dir_path)
  File "/usr/local/lib/python3.12/site-packages/synapse/config/_base.py", line 880, in generate_missing_files
    self.invoke_all("generate_files", config_dict, config_dir_path)
  File "/usr/local/lib/python3.12/site-packages/synapse/config/_base.py", line 443, in invoke_all
    res[config_class.section] = getattr(config, func_name)(*args, **kwargs)
                                ^^^^^^^^^^^^^^^^^^^^^^^^^^^^^^^^^^^^^^^^^^^
  File "/usr/local/lib/python3.12/site-packages/synapse/config/logger.py", line 198, in generate_files
    with open(log_config, "w") as log_config_file:
         ^^^^^^^^^^^^^^^^^^^^^
PermissionError: [Errno 13] Permission denied: '/data/rubberroomwithrats.com.log.config'
Generating log config file /data/rubberroomwithrats.com.log.config which will log to /homeserver.log
Starting synapse with args -m synapse.app.homeserver --config-path /data/homeserver.yaml
Traceback (most recent call last):
  File "<frozen runpy>", line 198, in _run_module_as_main
  File "<frozen runpy>", line 88, in _run_code
  File "/usr/local/lib/python3.12/site-packages/synapse/app/homeserver.py", line 421, in <module>
    main()
  File "/usr/local/lib/python3.12/site-packages/synapse/app/homeserver.py", line 411, in main
    hs = setup(sys.argv[1:])
         ^^^^^^^^^^^^^^^^^^^
  File "/usr/local/lib/python3.12/site-packages/synapse/app/homeserver.py", line 320, in setup
    config = HomeServerConfig.load_or_generate_config(
             ^^^^^^^^^^^^^^^^^^^^^^^^^^^^^^^^^^^^^^^^^
  File "/usr/local/lib/python3.12/site-packages/synapse/config/_base.py", line 833, in load_or_generate_config
    obj.generate_missing_files(config_dict, config_dir_path)
  File "/usr/local/lib/python3.12/site-packages/synapse/config/_base.py", line 880, in generate_missing_files
    self.invoke_all("generate_files", config_dict, config_dir_path)
  File "/usr/local/lib/python3.12/site-packages/synapse/config/_base.py", line 443, in invoke_all
    res[config_class.section] = getattr(config, func_name)(*args, **kwargs)
                                ^^^^^^^^^^^^^^^^^^^^^^^^^^^^^^^^^^^^^^^^^^^
  File "/usr/local/lib/python3.12/site-packages/synapse/config/logger.py", line 198, in generate_files
    with open(log_config, "w") as log_config_file:
         ^^^^^^^^^^^^^^^^^^^^^
PermissionError: [Errno 13] Permission denied: '/data/rubberroomwithrats.com.log.config'
Generating log config file /data/rubberroomwithrats.com.log.config which will log to /homeserver.log
Starting synapse with args -m synapse.app.homeserver --config-path /data/homeserver.yaml
Traceback (most recent call last):
  File "<frozen runpy>", line 198, in _run_module_as_main
  File "<frozen runpy>", line 88, in _run_code
  File "/usr/local/lib/python3.12/site-packages/synapse/app/homeserver.py", line 421, in <module>
    main()
  File "/usr/local/lib/python3.12/site-packages/synapse/app/homeserver.py", line 411, in main
    hs = setup(sys.argv[1:])
         ^^^^^^^^^^^^^^^^^^^
  File "/usr/local/lib/python3.12/site-packages/synapse/app/homeserver.py", line 320, in setup
    config = HomeServerConfig.load_or_generate_config(
             ^^^^^^^^^^^^^^^^^^^^^^^^^^^^^^^^^^^^^^^^^
  File "/usr/local/lib/python3.12/site-packages/synapse/config/_base.py", line 833, in load_or_generate_config
    obj.generate_missing_files(config_dict, config_dir_path)
  File "/usr/local/lib/python3.12/site-packages/synapse/config/_base.py", line 880, in generate_missing_files
    self.invoke_all("generate_files", config_dict, config_dir_path)
  File "/usr/local/lib/python3.12/site-packages/synapse/config/_base.py", line 443, in invoke_all
    res[config_class.section] = getattr(config, func_name)(*args, **kwargs)
                                ^^^^^^^^^^^^^^^^^^^^^^^^^^^^^^^^^^^^^^^^^^^
  File "/usr/local/lib/python3.12/site-packages/synapse/config/logger.py", line 198, in generate_files
    with open(log_config, "w") as log_config_file:
         ^^^^^^^^^^^^^^^^^^^^^
PermissionError: [Errno 13] Permission denied: '/data/rubberroomwithrats.com.log.config'
Generating log config file /data/rubberroomwithrats.com.log.config which will log to /homeserver.log
Starting synapse with args -m synapse.app.homeserver --config-path /data/homeserver.yaml
Traceback (most recent call last):
  File "<frozen runpy>", line 198, in _run_module_as_main
  File "<frozen runpy>", line 88, in _run_code
  File "/usr/local/lib/python3.12/site-packages/synapse/app/homeserver.py", line 421, in <module>
    main()
  File "/usr/local/lib/python3.12/site-packages/synapse/app/homeserver.py", line 411, in main
    hs = setup(sys.argv[1:])
         ^^^^^^^^^^^^^^^^^^^
  File "/usr/local/lib/python3.12/site-packages/synapse/app/homeserver.py", line 320, in setup
    config = HomeServerConfig.load_or_generate_config(
             ^^^^^^^^^^^^^^^^^^^^^^^^^^^^^^^^^^^^^^^^^
  File "/usr/local/lib/python3.12/site-packages/synapse/config/_base.py", line 833, in load_or_generate_config
    obj.generate_missing_files(config_dict, config_dir_path)
  File "/usr/local/lib/python3.12/site-packages/synapse/config/_base.py", line 880, in generate_missing_files
    self.invoke_all("generate_files", config_dict, config_dir_path)
  File "/usr/local/lib/python3.12/site-packages/synapse/config/_base.py", line 443, in invoke_all
    res[config_class.section] = getattr(config, func_name)(*args, **kwargs)
                                ^^^^^^^^^^^^^^^^^^^^^^^^^^^^^^^^^^^^^^^^^^^
  File "/usr/local/lib/python3.12/site-packages/synapse/config/logger.py", line 198, in generate_files
    with open(log_config, "w") as log_config_file:
         ^^^^^^^^^^^^^^^^^^^^^
PermissionError: [Errno 13] Permission denied: '/data/rubberroomwithrats.com.log.config'
Generating log config file /data/rubberroomwithrats.com.log.config which will log to /homeserver.log
Starting synapse with args -m synapse.app.homeserver --config-path /data/homeserver.yaml
Traceback (most recent call last):
  File "<frozen runpy>", line 198, in _run_module_as_main
  File "<frozen runpy>", line 88, in _run_code
  File "/usr/local/lib/python3.12/site-packages/synapse/app/homeserver.py", line 421, in <module>
    main()
  File "/usr/local/lib/python3.12/site-packages/synapse/app/homeserver.py", line 411, in main
    hs = setup(sys.argv[1:])
         ^^^^^^^^^^^^^^^^^^^
  File "/usr/local/lib/python3.12/site-packages/synapse/app/homeserver.py", line 320, in setup
    config = HomeServerConfig.load_or_generate_config(
             ^^^^^^^^^^^^^^^^^^^^^^^^^^^^^^^^^^^^^^^^^
  File "/usr/local/lib/python3.12/site-packages/synapse/config/_base.py", line 833, in load_or_generate_config
    obj.generate_missing_files(config_dict, config_dir_path)
  File "/usr/local/lib/python3.12/site-packages/synapse/config/_base.py", line 880, in generate_missing_files
    self.invoke_all("generate_files", config_dict, config_dir_path)
  File "/usr/local/lib/python3.12/site-packages/synapse/config/_base.py", line 443, in invoke_all
    res[config_class.section] = getattr(config, func_name)(*args, **kwargs)
                                ^^^^^^^^^^^^^^^^^^^^^^^^^^^^^^^^^^^^^^^^^^^
  File "/usr/local/lib/python3.12/site-packages/synapse/config/logger.py", line 198, in generate_files
    with open(log_config, "w") as log_config_file:
         ^^^^^^^^^^^^^^^^^^^^^
PermissionError: [Errno 13] Permission denied: '/data/rubberroomwithrats.com.log.config'
Generating log config file /data/rubberroomwithrats.com.log.config which will log to /homeserver.log
Starting synapse with args -m synapse.app.homeserver --config-path /data/homeserver.yaml
Traceback (most recent call last):
  File "<frozen runpy>", line 198, in _run_module_as_main
  File "<frozen runpy>", line 88, in _run_code
  File "/usr/local/lib/python3.12/site-packages/synapse/app/homeserver.py", line 421, in <module>
    main()
  File "/usr/local/lib/python3.12/site-packages/synapse/app/homeserver.py", line 411, in main
    hs = setup(sys.argv[1:])
         ^^^^^^^^^^^^^^^^^^^
  File "/usr/local/lib/python3.12/site-packages/synapse/app/homeserver.py", line 320, in setup
    config = HomeServerConfig.load_or_generate_config(
             ^^^^^^^^^^^^^^^^^^^^^^^^^^^^^^^^^^^^^^^^^
  File "/usr/local/lib/python3.12/site-packages/synapse/config/_base.py", line 833, in load_or_generate_config
    obj.generate_missing_files(config_dict, config_dir_path)
  File "/usr/local/lib/python3.12/site-packages/synapse/config/_base.py", line 880, in generate_missing_files
    self.invoke_all("generate_files", config_dict, config_dir_path)
  File "/usr/local/lib/python3.12/site-packages/synapse/config/_base.py", line 443, in invoke_all
    res[config_class.section] = getattr(config, func_name)(*args, **kwargs)
                                ^^^^^^^^^^^^^^^^^^^^^^^^^^^^^^^^^^^^^^^^^^^
  File "/usr/local/lib/python3.12/site-packages/synapse/config/logger.py", line 198, in generate_files
    with open(log_config, "w") as log_config_file:
         ^^^^^^^^^^^^^^^^^^^^^
PermissionError: [Errno 13] Permission denied: '/data/rubberroomwithrats.com.log.config'
Generating log config file /data/rubberroomwithrats.com.log.config which will log to /homeserver.log
Starting synapse with args -m synapse.app.homeserver --config-path /data/homeserver.yaml
Traceback (most recent call last):
  File "<frozen runpy>", line 198, in _run_module_as_main
  File "<frozen runpy>", line 88, in _run_code
  File "/usr/local/lib/python3.12/site-packages/synapse/app/homeserver.py", line 421, in <module>
    main()
  File "/usr/local/lib/python3.12/site-packages/synapse/app/homeserver.py", line 411, in main
    hs = setup(sys.argv[1:])
         ^^^^^^^^^^^^^^^^^^^
  File "/usr/local/lib/python3.12/site-packages/synapse/app/homeserver.py", line 320, in setup
    config = HomeServerConfig.load_or_generate_config(
             ^^^^^^^^^^^^^^^^^^^^^^^^^^^^^^^^^^^^^^^^^
  File "/usr/local/lib/python3.12/site-packages/synapse/config/_base.py", line 833, in load_or_generate_config
    obj.generate_missing_files(config_dict, config_dir_path)
  File "/usr/local/lib/python3.12/site-packages/synapse/config/_base.py", line 880, in generate_missing_files
    self.invoke_all("generate_files", config_dict, config_dir_path)
  File "/usr/local/lib/python3.12/site-packages/synapse/config/_base.py", line 443, in invoke_all
    res[config_class.section] = getattr(config, func_name)(*args, **kwargs)
                                ^^^^^^^^^^^^^^^^^^^^^^^^^^^^^^^^^^^^^^^^^^^
  File "/usr/local/lib/python3.12/site-packages/synapse/config/logger.py", line 198, in generate_files
    with open(log_config, "w") as log_config_file:
         ^^^^^^^^^^^^^^^^^^^^^
PermissionError: [Errno 13] Permission denied: '/data/rubberroomwithrats.com.log.config'
Generating log config file /data/rubberroomwithrats.com.log.config which will log to /homeserver.log
Starting synapse with args -m synapse.app.homeserver --config-path /data/homeserver.yaml
Traceback (most recent call last):
  File "<frozen runpy>", line 198, in _run_module_as_main
  File "<frozen runpy>", line 88, in _run_code
  File "/usr/local/lib/python3.12/site-packages/synapse/app/homeserver.py", line 421, in <module>
    main()
  File "/usr/local/lib/python3.12/site-packages/synapse/app/homeserver.py", line 411, in main
    hs = setup(sys.argv[1:])
         ^^^^^^^^^^^^^^^^^^^
  File "/usr/local/lib/python3.12/site-packages/synapse/app/homeserver.py", line 320, in setup
    config = HomeServerConfig.load_or_generate_config(
             ^^^^^^^^^^^^^^^^^^^^^^^^^^^^^^^^^^^^^^^^^
  File "/usr/local/lib/python3.12/site-packages/synapse/config/_base.py", line 833, in load_or_generate_config
    obj.generate_missing_files(config_dict, config_dir_path)
  File "/usr/local/lib/python3.12/site-packages/synapse/config/_base.py", line 880, in generate_missing_files
    self.invoke_all("generate_files", config_dict, config_dir_path)
  File "/usr/local/lib/python3.12/site-packages/synapse/config/_base.py", line 443, in invoke_all
    res[config_class.section] = getattr(config, func_name)(*args, **kwargs)
                                ^^^^^^^^^^^^^^^^^^^^^^^^^^^^^^^^^^^^^^^^^^^
  File "/usr/local/lib/python3.12/site-packages/synapse/config/logger.py", line 198, in generate_files
    with open(log_config, "w") as log_config_file:
         ^^^^^^^^^^^^^^^^^^^^^
PermissionError: [Errno 13] Permission denied: '/data/rubberroomwithrats.com.log.config'
Generating log config file /data/rubberroomwithrats.com.log.config which will log to /homeserver.log
Starting synapse with args -m synapse.app.homeserver --config-path /data/homeserver.yaml
Traceback (most recent call last):
  File "<frozen runpy>", line 198, in _run_module_as_main
  File "<frozen runpy>", line 88, in _run_code
  File "/usr/local/lib/python3.12/site-packages/synapse/app/homeserver.py", line 421, in <module>
    main()
  File "/usr/local/lib/python3.12/site-packages/synapse/app/homeserver.py", line 411, in main
    hs = setup(sys.argv[1:])
         ^^^^^^^^^^^^^^^^^^^
  File "/usr/local/lib/python3.12/site-packages/synapse/app/homeserver.py", line 320, in setup
    config = HomeServerConfig.load_or_generate_config(
             ^^^^^^^^^^^^^^^^^^^^^^^^^^^^^^^^^^^^^^^^^
  File "/usr/local/lib/python3.12/site-packages/synapse/config/_base.py", line 833, in load_or_generate_config
    obj.generate_missing_files(config_dict, config_dir_path)
  File "/usr/local/lib/python3.12/site-packages/synapse/config/_base.py", line 880, in generate_missing_files
    self.invoke_all("generate_files", config_dict, config_dir_path)
  File "/usr/local/lib/python3.12/site-packages/synapse/config/_base.py", line 443, in invoke_all
    res[config_class.section] = getattr(config, func_name)(*args, **kwargs)
                                ^^^^^^^^^^^^^^^^^^^^^^^^^^^^^^^^^^^^^^^^^^^
  File "/usr/local/lib/python3.12/site-packages/synapse/config/logger.py", line 198, in generate_files
    with open(log_config, "w") as log_config_file:
         ^^^^^^^^^^^^^^^^^^^^^
PermissionError: [Errno 13] Permission denied: '/data/rubberroomwithrats.com.log.config'
Generating log config file /data/rubberroomwithrats.com.log.config which will log to /homeserver.log
Starting synapse with args -m synapse.app.homeserver --config-path /data/homeserver.yaml
Traceback (most recent call last):
  File "<frozen runpy>", line 198, in _run_module_as_main
  File "<frozen runpy>", line 88, in _run_code
  File "/usr/local/lib/python3.12/site-packages/synapse/app/homeserver.py", line 421, in <module>
    main()
  File "/usr/local/lib/python3.12/site-packages/synapse/app/homeserver.py", line 411, in main
    hs = setup(sys.argv[1:])
         ^^^^^^^^^^^^^^^^^^^
  File "/usr/local/lib/python3.12/site-packages/synapse/app/homeserver.py", line 320, in setup
    config = HomeServerConfig.load_or_generate_config(
             ^^^^^^^^^^^^^^^^^^^^^^^^^^^^^^^^^^^^^^^^^
  File "/usr/local/lib/python3.12/site-packages/synapse/config/_base.py", line 833, in load_or_generate_config
    obj.generate_missing_files(config_dict, config_dir_path)
  File "/usr/local/lib/python3.12/site-packages/synapse/config/_base.py", line 880, in generate_missing_files
    self.invoke_all("generate_files", config_dict, config_dir_path)
  File "/usr/local/lib/python3.12/site-packages/synapse/config/_base.py", line 443, in invoke_all
    res[config_class.section] = getattr(config, func_name)(*args, **kwargs)
                                ^^^^^^^^^^^^^^^^^^^^^^^^^^^^^^^^^^^^^^^^^^^
  File "/usr/local/lib/python3.12/site-packages/synapse/config/logger.py", line 198, in generate_files
    with open(log_config, "w") as log_config_file:
         ^^^^^^^^^^^^^^^^^^^^^
PermissionError: [Errno 13] Permission denied: '/data/rubberroomwithrats.com.log.config'
Generating log config file /data/rubberroomwithrats.com.log.config which will log to /homeserver.log
